Workbook
Name \A: '[1]last qrt2001'!#REF!
Name \B: '[1]last qrt2001'!#REF!
Name \C: [2]A!#REF!
Name \D: [2]A!#REF!
Name \E: [2]A!#REF!
Name \I: [2]A!#REF!
Name \R: '[1]last qrt2001'!#REF!
Name \S: '[1]last qrt2001'!#REF!
Name \T: '[3]Notes1-5(old)'!#REF!
Name _______Jan1: '[4]Cons '!$C$8
Name _______Jan1: '[4]Cons '!$C$8
Name _______Jan1: '[4]Cons '!$C$8
Name _______Jan1: '[5]Cons '!$C$8
Name ___bal95: #REF!
Name ___bal96: #REF!
Name ___bal97: #REF!
Name ___bal98: #REF!
Name ___bal99: #REF!
Name ___bla97: #REF!
Name ___EPS2: #REF!
Name ___inc95: #REF!
Name ___inc96: #REF!
Name ___inc97: #REF!
Name ___inc98: #REF!
Name ___inc99: #REF!
Name ___Jan1: '[6]Cons '!$C$8
Name ___Jan1: '[6]Cons '!$C$8
Name ___Jan1: '[6]Cons '!$C$8
Name ___Jan1: '[7]Cons '!$C$8
Name ___Man10: [8]Notes!#REF!
Name ___Man10: [8]Notes!#REF!
Name ___Man10: [8]Notes!#REF!
Name ___Man10: [9]Notes!#REF!
Name ___RAT95: #REF!
Name ___RAT96: #REF!
Name ___RAT97: #REF!
Name ___RAT98: #REF!
Name ___RAT99: #REF!
Name __a1: '[14]Sheet1 '!$B$1:$O$99
Name __bal95: #REF!
Name __bal96: #REF!
Name __bal97: #REF!
Name __bal98: #REF!
Name __bal99: #REF!
Name __bla97: #REF!
Name __EPS2: #REF!
Name __inc95: #REF!
Name __inc96: #REF!
Name __inc97: #REF!
Name __inc98: #REF!
Name __inc99: #REF!
Name __Jan1: '[4]Cons '!$C$8
Name __Jan1: '[4]Cons '!$C$8
Name __Jan1: '[4]Cons '!$C$8
Name __Jan1: '[5]Cons '!$C$8
Name __RAT95: #REF!
Name __RAT96: #REF!
Name __RAT97: #REF!
Name __RAT98: #REF!
Name __RAT99: #REF!

Sheet Dashboard 
B1: Amount in PKR
B2: Annual
B3: OSR
C4: 46204 | D4: 46235 | E4: 46266 | F4: 46296 | G4: 46327 | H4: 46357 | I4: 46388 | J4: 46419 | K4: 46447 | L4: 46478 | M4: 46508 | N4: 46539 | O4: Totals
B5: Savings OSR | C5: ='Treasury Bank Profits mappe (2)'!F20 -> 97378802 | O5: =SUM(C5:N5) -> 97378802
B6: Savings RPA | C6: ='Treasury Bank Profits mappe (2)'!F48 -> 1150066.3 | O6: =SUM(C6:N6) -> 1150066.3
B7: Savings Escrow | C7: ='Treasury Bank Profits mappe (2)'!F59 -> 995416.19 | O7: =SUM(C7:N7) -> 995416.19
B8: Tbills | O8: =SUM(C8:N8) -> 0
B9: TDR | O9: =SUM(C9:N9) -> 0
B10: Buy Sell | O10: =SUM(C10:N10) -> 0
B11: Total | C11: =SUM(C5:C10) -> 99524284 | D11: =SUM(D5:D10) -> 0 | E11: =SUM(E5:E10) -> 0 | F11: =SUM(F5:F10) -> 0 | G11: =SUM(G5:G10) -> 0 | H11: =SUM(H5:H10) -> 0 | I11: =SUM(I5:I10) -> 0 | J11: =SUM(J5:J10) -> 0 | ... N11: =SUM(N5:N10) -> 0 | O11: =SUM(C11:N11) -> 99524284
N16: Amount in PKR
B17: FIP
C18: 46204 | D18: 46235 | E18: 46266 | F18: 46296 | G18: 46327 | H18: 46357 | I18: 46388 | J18: 46419 | K18: 46447 | L18: 46478 | M18: 46508 | N18: 46539 | O18: Totals
B19: Savings FIP | M19: =#REF! -> #REF! | N19: =#REF! -> #REF! | O19: =SUM(C19:N19) -> #REF!
B20: Total | C20: =SUM(C19) -> 0 | D20: =SUM(D19) -> 0 | E20: =SUM(E19) -> 0 | F20: =SUM(F19) -> 0 | G20: =SUM(G19) -> 0 | H20: =SUM(H19) -> 0 | I20: =SUM(I19) -> 0 | J20: =SUM(J19) -> 0 | ... N20: =SUM(N19) -> #REF! | O20: =SUM(C20:N20) -> #REF!
N22: Amount in PKR
B23: GF | O23: Totals
C24: 46204 | D24: 46235 | E24: 46266 | F24: 46296 | G24: 46327 | H24: 46357 | I24: 46388 | J24: 46419 | K24: 46447 | L24: 46478 | M24: 46508 | N24: 46539
B25: Savings | O25: =SUM(C25:N25) -> 0
B26: Tbills | O26: =SUM(C26:N26) -> 0
B27: Total | C27: =SUM(C25:C26) -> 0 | D27: =SUM(D25:D26) -> 0 | E27: =SUM(E25:E26) -> 0 | F27: =SUM(F25:F26) -> 0 | G27: =SUM(G25:G26) -> 0 | H27: =SUM(H25:H26) -> 0 | I27: =SUM(I25:I26) -> 0 | J27: =SUM(J25:J26) -> 0 | ... N27: =SUM(N25:N26) -> 0 | O27: =SUM(C27:N27) -> 0

Sheet Quarterly
B1: Amount in PKR
B2: Q1
B3: OSR
C4: Q1 | D4: Q2 | E4: Q3 | F4: Q4 | G4: Totals
B5: Savings OSR | C5: ='Treasury Bank Profits mappe (2)'!G21 -> 1.6572198e+08 | G5: =SUM(C5:F5) -> 1.6572198e+08
B6: Savings RPA | C6: ='Treasury Bank Profits mappe (2)'!G49 -> 2614080.9 | G6: =SUM(C6:F6) -> 2614080.9
B7: Savings Escrow | C7: ='Treasury Bank Profits mappe (2)'!G60 -> 2000395.6 | G7: =SUM(C7:F7) -> 2000395.6
B8: Tbills | G8: =SUM(C8:F8) -> 0
B9: TDR | C9: =SUM('New TDR Mapped'!F9:H9) -> 42534247 | G9: =SUM(C9:F9) -> 42534247
B10: Buy Sell | C10: =SUM('New Buy Sell Mapped'!J2:J6) -> 46074967 | G10: =SUM(C10:F10) -> 46074967
B11: Total | C11: =SUM(C5:C10) -> 2.5894567e+08 | D11: =SUM(D5:D10) -> 0 | E11: =SUM(E5:E10) -> 0 | F11: =SUM(F5:F10) -> 0 | G11: =SUM(C11:F11) -> 2.5894567e+08
B15: FIP
C16: Q1 | D16: Q2 | E16: Q3 | F16: Q4 | G16: Totals
B17: Savings FIP | C17: =SUM('Treasury Bank Profits mappe (2)'!G39) -> 5189303 | E17: ='Treasury Bank Profits mappe (2)'!H38 -> 0 | F17: ='Treasury Bank Profits mappe (2)'!I38 -> 0 | G17: =SUM(C17:F17) -> 5189303
B18: Total | C18: =SUM(C17) -> 5189303 | D18: =SUM(D17) -> 0 | E18: =SUM(E17) -> 0 | F18: =SUM(F17) -> 0 | G18: =SUM(C18:F18) -> 5189303
B22: GF | G22: Totals
C23: Q1 | D23: Q2 | E23: Q3 | F23: Q4
B24: Savings | C24: ='Treasury Bank Profits mappe (2)'!G31 -> 2729188.8 | E24: ='Treasury Bank Profits mappe (2)'!H30 -> 0 | F24: ='Treasury Bank Profits mappe (2)'!I30 -> 0 | G24: =SUM(C24:F24) -> 2729188.8
B25: Total | C25: =SUM(C24:C24) -> 2729188.8 | D25: =SUM(D24:D24) -> 0 | E25: =SUM(E24:E24) -> 0 | F25: =SUM(F24:F24) -> 0 | G25: =SUM(C25:F25) -> 2729188.8

Sheet Treasury Bank Profits mappe (2)
A1: Karandaaz Pakistan | B1: Matched with TB as of May 31
A2: Sr.no | C2: Account Title | D2: Account Number | E2: Bank Name | F2: 46204 | G2: 46235 | H2: 46266 | I2: 46296 | J2: 46327 | K2: 46357 | L2: 46388 | M2: 46419 | N2: 46447 | O2: 46478 | P2: 46508 | Q2: 46539
A3: 3 | B3: EAGR | C3: Karandaaz Pakistan Investments | D3: 9134 | E3: UBL | F3: 12032.57 | G3: 1187356.6
A4: 3 | B4: EAGR | C4: Karandaaz Pakistan OWN SOURCE REVENUE | D4: 9172 | E4: UBL | F4: 1317515.9 | G4: 1420639.7
C5: Karandaaz Pakistan WV Greenfin | E5: UBL | F5: 47.94 | G5: 5171.73
A6: 4 | B6: EAGR | C6: Karandaaz Pakistan | D6: 1006023474 | E6: BAFL | F6: 374560.34 | G6: 714772.99
A7: 6 | B7: EAGR | C7: Karandaaz Pakistan ORIX CAPITAL | D7: 1006155292 | E7: BAFL | F7: 285203.67 | G7: 219948.64
A8: 7 | B8: EAGR | C8: Karandaaz Pakistan TPPL | D8: 1006155289 | E8: BAFL | F8: 77.83 | G8: 32.7
A9: 8 | B9: EAGR | C9: Karandaaz Pakistan OWN SOURCE REVENUE* | D9: 1006155288 | E9: BAFL | F9: 15667607 | G9: 6184330
A10: 9 | B10: EAGR | C10: Karandaaz Pakistan CiC | D10: 1698 | E10: BAFL | F10: 618682.73 | G10: 1128766.6
A11: 9 | B11: EAGR | C11: Karandaaz Pakistan Investments | D11: 2280 | E11: BAFL | F11: 59343.81 | G11: 49755.65
A12: 10 | B12: EAGR | C12: Karandaaz Pakistan Reserve* | D12: 0874-79009966-01 | E12: HBL | F12: 2267.07 | G12: 2286.32
A13: 11 | B13: EAGR | C13: Karandaaz Pakistan OWN SOURCE REVENUE* | D13: 06-02-37-20614-714-146790 | E13: HMB
A14: 12 | B14: EAGR | C14: Karandaaz Pakistan Operational | D14: 0002253139 | E14: JSBL
A15: 13 | B15: EAGR | C15: Karandaaz Pakistan OWN SOURCE REVENUE | D15: 3238390000003107 | E15: Faysal | F15: 66962609 | G15: 45218697
A16: 14 | B16: WV GCF | C16: Karandaaz Pakistan WV Greenfin | D16: 3238390000003722 | E16: Faysal | F16: 2231799.7 | G16: 2306909.1
A17: 16 | B17: EAGR | C17: Karandaaz Pakistan Own Source Revenue | D17: 0010137809770010 | E17: ABL
A18: 17 | B18: EAGR | C18: Karandaaz Pakistan-Own Source Revenue | D18: 2001412216 | E18: SAMBA | F18: 9847054.7 | G18: 9904512.4
B19: EAGR | C19: Karandaaz Pakistan-Own Source Revenue | D19: 2001543507 | E19: BIPL
F20: =SUM(F3:F19) -> 97378802 | G20: =SUM(G3:G19) -> 68343179 | H20: =SUM(H3:H19) -> 0 | I20: =SUM(I3:I19) -> 0 | J20: =SUM(J3:J19) -> 0 | K20: =SUM(K3:K19) -> 0 | L20: =SUM(L3:L19) -> 0 | M20: =SUM(M3:M19) -> 0 | ... Q20: =SUM(Q3:Q19) -> 0
G21: =SUM(F20:H20) -> 1.6572198e+08 | J21: =SUM(I20:K20) -> 0 | M21: =SUM(L20:N20) -> 0 | P21: =SUM(O20:Q20) -> 0
G22: Jul-Sept | J22: Oct-Dec | M22: Jan-Mar | P22: Apr-Jun
A23: BMGF | C23: Account Title | D23: Account Number | E23: Bank Name | F23: 46204 | G23: 46235 | H23: 46266 | I23: 46296 | J23: 46327 | K23: 46357 | L23: 46388 | M23: 46419 | N23: 46447 | O23: 46478 | P23: 46508 | Q23: 46539
A24: 1 | B24: BMGF | C24: Karandaaz Pakistan BMGF | D24: 1006155298 | E24: BAFL | F24: 1243549.2 | G24: 466488.21
A25: =A24+1 -> 2 | B25: BMGF | C25: Karandaaz Pakistan (BMGF - Ehsaas) | D25: 1009045100 | E25: BAFL | F25: 283995.28 | G25: 97617.89
A26: =A25+1 -> 3 | B26: BMGF | C26: Karandaaz Pakistan (BMGF CT) | D26: 1009045134 | E26: BAFL | F26: 147812.23 | G26: 108363.34
C27: Karandaaz Pakistan (BMGF Raast) | D27: 1010801269 | E27: BAFL | F27: 119615.29 | G27: 68629.91
C28: Karandaaz Pakistan (BMGF FBR) | E28: BAFL | G28: 161184.22
A29: 4 | B29: BMGF | C29: Karandaaz Pakistan BMGF | D29: 231422152 | E29: UBL | F29: 15978.9 | G29: 15954.37
F30: =SUM(F24:F29) -> 1810950.9 | G30: =SUM(G24:G29) -> 918237.94 | H30: =SUM(H24:H29) -> 0 | I30: =SUM(I24:I29) -> 0 | J30: =SUM(J24:J29) -> 0 | K30: =SUM(K24:K29) -> 0 | L30: =SUM(L24:L29) -> 0 | M30: =SUM(M24:M29) -> 0 | ... Q30: =SUM(Q24:Q29) -> 0
G31: =SUM(F30:H30) -> 2729188.8 | J31: =SUM(I30:K30) -> 0 | M31: =SUM(L30:N30) -> 0 | P31: =SUM(O30:Q30) -> 0
G32: Jul-Sept | J32: Oct-Dec | M32: Jan-Mar | P32: Apr-Jun
A34: FIP | C34: Account Title | D34: Account Number | E34: Bank Name | F34: 46204 | G34: 46235 | H34: 46266 | I34: 46296 | J34: 46327 | K34: 46357 | L34: 46388 | M34: 46419 | N34: 46447 | O34: 46478 | P34: 46508 | Q34: 46539
A35: 1 | B35: FIP | C35: Karandaaz Pakistan FIP | D35: 1008986958 | E35: BAFL | F35: 145601.9 | G35: 68245.16
A36: 2 | B36: FIP | C36: Karandaaz Pakistan-FIP* | D36: 262115182 | E36: UBL | F36: 2529629.7 | G36: 2445826.3
A37: 3 | B37: FIP | C37: KARANDAAZ PAKISTAN FIP | D37: 6-2-37-20614-714-153581 | E37: HMB
F38: =SUM(F35:F37) -> 2675231.6 | G38: =SUM(G35:G37) -> 2514071.5 | H38: =SUM(H35:H37) -> 0 | I38: =SUM(I35:I37) -> 0 | J38: =SUM(J35:J37) -> 0 | K38: =SUM(K35:K37) -> 0 | L38: =SUM(L35:L37) -> 0 | M38: =SUM(M35:M37) -> 0 | ... Q38: =SUM(Q35:Q37) -> 0
G39: =SUM(F38:H38) -> 5189303 | J39: =SUM(I38:K38) -> 0 | M39: =SUM(L38:N38) -> 0 | P39: =SUM(O38:Q38) -> 0
G40: Jul-Sept | J40: Oct-Dec | M40: Jan-Mar | P40: Apr-Jun
A41: RPA | C41: Account Title | D41: Account Number | E41: Bank Name | F41: 46204 | G41: 46235 | H41: 46266 | I41: 46296 | J41: 46327 | K41: 46357 | L41: 46388 | M41: 46419 | N41: 46447 | O41: 46478 | P41: 46508 | Q41: 46539
...

Sheet New TDR Mapped
A1: Bank | B1: Account Title | C1: Amount | D1: Comments | E1: Inflow Date
A5: Currently Booked TDRs
C6: Booked On | D6: Profit Rate | E6: Amount | F6: July | G6: August | H6: September
A7: MIB | B7: Karandaaz Pakistan | C7: 46203 | D7: 0.1125 | E7: 1000000000 | F7: =$E$7*$D$7*31/365 -> 9554794.5 | G7: =$E$7*$D$7*31/365 -> 9554794.5 | H7: =$E$7*$D$7*30/365 -> 9246575.3
A8: BIPL | B8: Karandaaz Pakistan Own Source Revenue | C8: 46203 | D8: 0.1125 | E8: 500000000 | F8: =E8*D8*31/365 -> 4777397.3 | G8: =$E$8*$D$8*31/365 -> 4777397.3 | H8: =$E$8*$D$8*30/365 -> 4623287.7
F9: =SUM(F7:F8) -> 14332192 | G9: =SUM(G7:G8) -> 14332192 | H9: =SUM(H7:H8) -> 13869863

Sheet New Buy Sell Mapped
A1: Bank | B1: Program | C1: Account Title | D1: No of Days | E1: Purchase date | F1: Maturity Date | G1: Profit Rate (p.a) | H1: Cheque Value | I1: Face Value | J1: Profit | K1: Profit By Krn | L1: Difference
A2: UBL | B2: OSR | C2: Karandaaz Pakistan Own Source Revenue | D2: =F2-E2 -> 22 | E2: 46231 | F2: 46253 | G2: 0.1173 | H2: 1999987518 | I2: 2014127558 | J2: =I2-H2 -> 14140040 | K2: =H2*G2*D2/365 -> 14140186 | L2: =K2-J2 -> 145.72315
A3: HMBL | B3: OSR | C3: Karandaaz Pakistan Own Source Revenue | D3: =F3-E3 -> 17 | E3: 46230 | F3: 46247 | G3: 0.1172 | H3: 999983711 | I3: 1005442329 | J3: =I3-H3 -> 5458618 | K3: =H3*G3*D3/365 -> 5458541.2 | L3: =K3-J3 -> -76.77864
A4: UBL | B4: OSR | C4: Karandaaz Pakistan Own Source Revenue | D4: =F4-E4 -> 14 | E4: 46251 | F4: 46265 | G4: 0.1182 | H4: 2.9999178e+09 | I4: 3013521300 | J4: =I4-H4 -> 13603523 | K4: =H4*G4*D4/365 -> 13600723 | L4: =K4-J4 -> -2799.9643
A5: UBL | B5: OSR | C5: Karandaaz Pakistan Own Source Revenue | D5: =F5-E5 -> 14 | E5: 46251 | F5: 46265 | G5: 0.1182 | H5: 1.0000057e+09 | I5: 1004540322 | J5: =I5-H5 -> 4534657.4 | K5: =H5*G5*D5/365 -> 4533724.3 | L5: =K5-J5 -> -933.12846
A6: UBL | B6: OSR | C6: Karandaaz Pakistan Own Source Revenue | D6: =F6-E6 -> 13 | E6: 46254 | F6: 46267 | G6: 0.117052 | H6: 2.0000369e+09 | I6: 2008375035 | J6: =I6-H6 -> 8338128.2 | K6: =H6*G6*D6/365 -> 8338104.5 | L6: =K6-J6 -> -23.631446
G10: =AVERAGE(G2:G6) -> 0.1175904 | J10: =SUM(J2:J3) -> 19598658
G11: Avg Rate | J11: Total

Sheet Treasury Bank Profits forcasted
A1: Karandaaz Pakistan | B1: Matched with TB as of 31st Jan | U1: MY TOTAL | V1: =S19+S27+S35 -> 1.0076081e+09
A2: Sr.no | C2: Account Title | D2: Bank A/c | E2: Bank Name | F2: July'25 | G2: Aug | H2: Sept | I2: October | J2: November | K2: December | L2: Jan | M2: Feb | N2: March | O2: April | P2: May | Q2: June | R2: Total | U2: GL BAL AS OF Jan 31st | V2: -7.9790264e+08
A3: 1 | B3: EAGR | C3: Karandaaz Pakistan DFID | D3: 231422923 | E3: UBL | G3: 26514 | H3: Closed | I3: Closed | J3: Closed | K3: Closed | L3: Closed | M3: Closed | N3: Closed | O3: Closed | P3: Closed | Q3: Closed | R3: =SUM(F3:Q3) -> 26514 | U3: Difference | V3: =V2+V1 -> 2.0970543e+08
A4: 3 | B4: EAGR | C4: Karandaaz Pakistan Investments | D4: 9134 | E4: UBL | F4: 5506585 | G4: 5506585 | H4: 5506585 | I4: 1566397.5 | J4: 3102250.2 | K4: =2629214.54+2094186.08 -> 4723400.6 | L4: 4371706.2 | M4: 3860707.5 | N4: 3941162.6 | O4: 0 | P4: 0 | R4: =SUBTOTAL(9,F4:Q4) -> 38085380
A5: 3 | B5: EAGR | C5: Karandaaz Pakistan OWN SOURCE REVENUE | D5: 9172 | E5: UBL | F5: 1216390.3 | G5: 1216390.3 | H5: 1216390.3 | I5: 2072281.3 | J5: 2925850.4 | K5: 6103589 | L5: =1307802.28+1967751.74 -> 3275554 | M5: 7788250.9 | N5: 10639562 | O5: 0 | P5: 0 | R5: =SUBTOTAL(9,F5:Q5) -> 36454258
A6: 4 | B6: EAGR | C6: Karandaaz Pakistan | D6: 1006023474 | E6: BAFL | F6: 305737 | G6: 486244.07 | H6: 193234.39 | I6: =146697.41+3547.95 -> 150245.36 | J6: 257170.07 | K6: 277764.5 | L6: 256624.39 | M6: 297433.18 | N6: 342034.54 | R6: =SUM(F6:Q6) -> 2566487.5 | U6: =U8+U9 -> 0
A7: 5 | B7: EAGR | C7: Karandaaz Pakistan DFID | D7: 1006024272 | E7: BAFL | F7: 1637214.5 | G7: 20894.88 | H7: 22509.87 | I7: 52507.16 | J7: Closed | K7: Closed | L7: Closed | M7: Closed | N7: Closed | O7: Closed | P7: Closed | Q7: Closed | R7: =SUM(F7:Q7) -> 1733126.4
A8: 6 | B8: EAGR | C8: Karandaaz Pakistan ORIX CAPITAL | D8: 1006155292 | E8: BAFL | F8: 1182085.8 | G8: 10240.43 | H8: 10338.94 | I8: 337931.83 | J8: 382024.66 | K8: 410482.89 | L8: 617477.6 | M8: 4476.3 | N8: 3656735.1 | R8: =SUM(F8:Q8) -> 6611793.5
A9: 7 | B9: EAGR | C9: Karandaaz Pakistan TPPL | D9: 1006155289 | E9: BAFL | F9: 102934.62 | G9: 98496.78 | H9: 99444.32 | I9: 103579.27 | J9: 853225.36 | K9: 1223477.8 | L9: 973248.17 | M9: 7062.64 | N9: 7876 | R9: =SUM(F9:Q9) -> 3469344.9
A10: 8 | B10: EAGR | C10: Karandaaz Pakistan OWN SOURCE REVENUE* | D10: 1006155288 | E10: BAFL | F10: 22522227 | G10: 32579788 | H10: 19774819 | I10: 26319781 | J10: 27920225 | K10: 24683730 | L10: 16691642 | M10: 4887529.8 | N10: 5157241.9 | R10: =SUM(F10:Q10) -> 1.8053698e+08
A11: 9 | B11: EAGR | C11: Karandaaz Pakistan CiC | D11: 1698 | E11: BAFL | F11: 1382968.5 | G11: 2143162.6 | H11: 2346921.4 | I11: 1900670.4 | J11: 1655609 | K11: 1791145.9 | L11: 381386.85 | M11: 390970.64 | N11: 344467.9 | R11: =SUM(F11:Q11) -> 12337303
A12: 9 | B12: EAGR | C12: Karandaaz Pakistan Investments | D12: 2280 | E12: BAFL | I12: 2602094.9 | J12: 5711710.3 | K12: 4426338.2 | L12: 1854292.5 | M12: 87014.93 | N12: 87014.9 | R12: =SUM(F12:Q12) -> 14768466
A13: 10 | B13: EAGR | C13: Karandaaz Pakistan Reserve* | D13: 0874-79009966-01 | E13: HBL | F13: 1968.9 | G13: 1984.79 | H13: 1936.26 | I13: 2016.42 | J13: 1967.12 | K13: 2048.56 | L13: 1956.4 | M13: 1777.39 | N13: 1976.86 | R13: =SUM(F13:Q13) -> 17632.7
A14: 11 | B14: EAGR | C14: Karandaaz Pakistan OWN SOURCE REVENUE* | D14: 06-02-37-20614-714-146790 | E14: HMB | F14: 503868.95 | G14: 503868.95 | H14: 503868.95 | L14: 34178 | N14: 591305 | R14: =SUM(F14:Q14) -> 2137089.9
A15: 12 | B15: EAGR | C15: Karandaaz Pakistan Operational | D15: 0002253139 | E15: JSBL | K15: 17477.17 | N15: 7000 | R15: =SUM(F15:Q15) -> 24477.17
A16: 13 | B16: EAGR | C16: Karandaaz Pakistan OWN SOURCE REVENUE | D16: 3238390000003107 | E16: Faysal | F16: 46036892 | G16: 46551177 | H16: 54817038 | I16: 48949285 | J16: =53355378.15+2512114 -> 55867492 | K16: 66883323 | L16: 83952078 | M16: =9117508.01+68524828.89 -> 77642337 | N16: 95461094 | R16: =SUM(F16:Q16) -> 5.7616072e+08
A17: 14 | B17: WV GCF | C17: Karandaaz Pakistan WV Greenfin | D17: 3238390000003722 | E17: Faysal | F17: 2344614 | G17: 2518745.1 | H17: 2508166.7 | I17: 2565342.9 | J17: =-43683+2251652.17 -> 2207969.2 | K17: 1933481.4 | L17: 933356 | M17: =106543.02+509166.02 -> 615709.04 | N17: 246427.87 | R17: =SUM(F17:Q17) -> 15873812
A18: 16 | B18: EAGR | C18: Karandaaz Pakistan Own Source Revenue | D18: 0010137809770010 | E18: ABL | R18: =SUM(F18:Q18) -> 0
A19: 17 | B19: EAGR | C19: Karandaaz Pakistan-Own Source Revenue | D19: 2001412216 | E19: SAMBA | F19: =259115.55+7670713 -> 7929828.5 | G19: =7740862.45 -> 7740862.5 | H19: 7559785.1 | I19: 7880799.8 | J19: 7696212.2 | K19: =7764213+261093.82 -> 8025306.8 | L19: 7626081.2 | M19: 6810513.1 | N19: 7599210.5 | R19: =SUM(F19:Q19) -> 68868600 | S19: =SUM(R3:R20) -> 9.6227642e+08
B20: EAGR | C20: Karandaaz Pakistan-KCBL II | D20: 2001543507 | E20: SAMBA | K20: 69873.86 | L20: 863606.99 | M20: 789747.23 | N20: 881204.6 | R20: =SUM(F20:Q20) -> 2604432.7
F21: =SUM(F3:F19) -> 90673315 | G21: =SUM(G3:G19) -> 99404954 | H21: =SUM(H3:H19) -> 94561038 | I21: =SUM(I3:I19) -> 94502933 | J21: =SUM(J3:J19) -> 1.0858171e+08 | K21: =SUM(K3:K20) -> 1.2057144e+08 | L21: =SUM(L3:L20) -> 1.2183319e+08 | M21: =SUM(M3:M20) -> 1.0318353e+08 | N21: =SUM(N3:N20) -> 1.2896431e+08 | O21: =SUM(O3:O20) -> 0 | P21: =SUM(P3:P20) -> 0 | Q21: =SUM(Q3:Q20) -> 0 | R21: =SUM(F21:Q21) -> 9.6227642e+08 | S21: Total | T21: =R21-S19 -> 0
G22: =SUM(F21:H21) -> 2.8463931e+08 | J22: =SUM(I21:K21) -> 3.2365608e+08 | M22: =SUM(L21:N21) -> 3.5398103e+08
G23: Jul-Sept | J23: Oct-Dec | M23: Jan-Mar
A24: BMGF | C24: Account Title | D24: Bank A/c | E24: Bank Name | F24: July'25 | G24: Aug | H24: Sept | I24: October | J24: November | K24: December | L24: Jan | M24: Feb | N24: March | O24: April | P24: May | Q24: June | R24: Total
A25: 1 | B25: BMGF | C25: Karandaaz Pakistan BMGF | D25: 1006155298 | E25: BAFL | F25: 888690.75 | G25: 1185738.3 | H25: 472893.35 | I25: =432114.54+43939.69 -> 476054.23 | J25: 287403.43 | K25: 1093974.1 | L25: 2039666.6 | M25: 596641.27 | N25: 730089.9 | R25: =SUM(F25:Q25) -> 7771151.8
A26: =A25+1 -> 2 | B26: BMGF | C26: Karandaaz Pakistan (BMGF - Ehsaas) | D26: 1009045100 | E26: BAFL | F26: 483471.76 | G26: 694131.04 | H26: 831423.35 | I26: 811374.49 | J26: 691352.67 | K26: 673279.89 | L26: 171831.17 | M26: 139065.49 | N26: 530408.2 | R26: =SUM(F26:Q26) -> 5026338.1
A27: =A26+1 -> 3 | B27: BMGF | C27: Karandaaz Pakistan (BMGF CT) | D27: 1009045134 | E27: BAFL | F27: 40023.53 | G27: 102031.25 | H27: 96754.54 | I27: 91072.28 | J27: 66662.41 | K27: 132754.54 | L27: 259714.56 | M27: 211683.32 | N27: 215771.2 | R27: =SUM(F27:Q27) -> 1216467.6 | S27: =SUM(R25:R28) -> 14125923
A28: 4 | B28: BMGF | C28: Karandaaz Pakistan BMGF | D28: 231422152 | E28: UBL | F28: 9964.3333 | G28: 9964.3333 | H28: 9964.3333 | I28: 13848.89 | J28: 13782.99 | K28: 14016.74 | L28: 13809.08 | M28: 12579.71 | N28: 14035.4 | R28: =SUM(F28:Q28) -> 111965.81
F29: =SUM(F25:F28) -> 1422150.4 | G29: =SUM(G25:G28) -> 1991864.9 | H29: =SUM(H25:H28) -> 1411035.6 | I29: =SUM(I25:I28) -> 1392349.9 | J29: =SUM(J25:J28) -> 1059201.5 | K29: =SUM(K25:K28) -> 1914025.2 | L29: =SUM(L25:L28) -> 2485021.4 | M29: =SUM(M25:M28) -> 959969.79 | ... Q29: =SUM(Q25:Q28) -> 0 | R29: =SUM(F29:Q29) -> 14125923 | S29: Total | T29: =S27-R29 -> 0
G30: =SUM(F29:H29) -> 4825050.8 | J30: =SUM(I29:K29) -> 4365576.6 | M30: =SUM(L29:N29) -> 4935295.9
G31: Jul-Sept | J31: Oct-Dec | M31: Jan-Mar
A32: FIP | C32: Account Title | D32: Bank A/c | E32: Bank Name | F32: July'25 | G32: Aug | H32: Sept | I32: October | J32: November | K32: December | L32: Jan | M32: Feb | N32: March | O32: April | P32: May | Q32: June | R32: Total
A33: 1 | B33: FIP | C33: Karandaaz Pakistan FIP | D33: 1008986958 | E33: BAFL | F33: 1631218.1 | G33: 387286.15 | H33: 363066.02 | I33: 241418.67 | J33: 213903.36 | K33: 198829.8 | L33: 373192.71 | M33: 335911.43 | N33: 372987.2 | R33: =SUM(F33:Q33) -> 4117813.4
A34: 2 | B34: FIP | C34: Karandaaz Pakistan-FIP* | D34: 262115182 | E34: UBL | F34: 3419337.3 | G34: 3419337.3 | H34: 3419337.3 | I34: 3627097.2 | J34: 3392741.8 | K34: 3123508.9 | L34: 2405713.7 | M34: 2037265.2 | N34: 2243581.2 | R34: =SUM(F34:Q34) -> 27087920
A35: 3 | B35: FIP | C35: KARANDAAZ PAKISTAN FIP | D35: 6-2-37-20614-714-153581 | E35: HMB | L35: 0 | M35: 0 | N35: 0 | O35: 0 | Q35: 0 | R35: =SUM(F35:Q35) -> 0 | S35: =SUM(R33:R35) -> 31205733
F36: =SUM(F33:F35) -> 5050555.4 | G36: =SUM(G33:G35) -> 3806623.5 | H36: =SUM(H33:H35) -> 3782403.4 | I36: =SUM(I33:I35) -> 3868515.8 | J36: =SUM(J33:J35) -> 3606645.1 | K36: =SUM(K33:K35) -> 3322338.7 | L36: =SUM(L33:L35) -> 2778906.4 | M36: =SUM(M33:M35) -> 2373176.7 | ... Q36: =SUM(Q33:Q35) -> 0 | R36: =SUM(F36:Q36) -> 31205733 | S36: Total | T36: =R36-S35 -> 0
G37: =SUM(F36:H36) -> 12639582 | J37: =SUM(I36:K36) -> 10797500 | M37: =SUM(L36:N36) -> 7768651.5
G38: Jul-Sept | J38: Oct-Dec | M38: Jan-Mar | R38: OSR Total | S38: =S19+S45+S54 -> 1.0180805e+09 | U38: MY TOTAL | V38: =S45 -> 41382051
A39: RPA | C39: Account Title | D39: Bank A/c | E39: Bank Name | F39: July'25 | G39: Aug | H39: Sept | I39: October | J39: November | K39: December | L39: Jan | M39: Feb | N39: March | O39: April | P39: May | Q39: June | R39: Total | U39: PO PROFIT GL AS PER Jan 31st | V39: -38926311
A40: 1 | B40: EAGR | C40: Karandaaz Pakistan BAFL | D40: 1005639975 | E40: BAFL | F40: 2575179.5 | G40: 2798067.8 | H40: 3508992.6 | I40: =4357126.93+102577.4 -> 4459704.3 | J40: 1675173.8 | K40: 2387880.3 | L40: 1520617.4 | M40: 684954.83 | N40: 1063375 | R40: =SUM(F40:Q40) -> 20673946 | U40: Difference | V40: =V38+V39 -> 2455740.8 | W40: Soneri
...

Sheet Treasury Bank Profits -Ayesha
A1: Karandaaz Pakistan | B1: Matched with TB as of 31st October
A2: Sr.no | B2: SEED | C2: Account Title | D2: Bank A/c | E2: Bank Name | F2: July'25 | G2: Aug | H2: Sept | I2: October | J2: November | K2: December | L2: Jan | M2: Feb | N2: March | O2: April | P2: May | Q2: June | R2: Total
A3: 1 | B3: EAGR | C3: Karandaaz Pakistan DFID | D3: 231422923 | E3: UBL | G3: 26514 | H3: Closed | I3: Closed | J3: Closed | K3: Closed | L3: Closed | M3: Closed | N3: Closed | O3: Closed | P3: Closed | Q3: Closed | R3: =SUM(F3:Q3) -> 26514
A4: 3 | B4: EAGR | C4: Karandaaz Pakistan Investments | D4: 9134 | E4: UBL | F4: 5506585 | G4: 5506585 | H4: 5506585 | I4: 1566397.5 | J4: 3102250.2 | K4: =2629214.54+2094186 -> 4723400.5 | L4: 0 | M4: 0 | N4: 0 | O4: 0 | P4: 0 | R4: =SUBTOTAL(9,F4:Q4) -> 25911803
A5: 3 | B5: EAGR | C5: Karandaaz Pakistan OWN SOURCE REVENUE | D5: 9172 | E5: UBL | F5: 1216390.3 | G5: 1216390.3 | H5: 1216390.3 | I5: 2072281.3 | J5: 2925850.4 | K5: 6103589 | L5: 0 | M5: 0 | N5: 0 | O5: 0 | P5: 0 | R5: =SUBTOTAL(9,F5:Q5) -> 14750892
A6: 4 | B6: EAGR | C6: Karandaaz Pakistan | D6: 1006023474 | E6: BAFL | F6: 305737 | G6: 486244.07 | H6: 193234.39 | I6: =146697.41+3547.95 -> 150245.36 | J6: 257170.07 | K6: 277764.5 | R6: =SUM(F6:Q6) -> 1670395.4
A7: 5 | B7: EAGR | C7: Karandaaz Pakistan DFID | D7: 1006024272 | E7: BAFL | F7: 1637214.5 | G7: 20894.88 | H7: 22509.87 | I7: 52507.16 | J7: Closed | K7: Closed | L7: Closed | M7: Closed | O7: Closed | P7: Closed | Q7: Closed | R7: =SUM(F7:Q7) -> 1733126.4
A8: 6 | B8: EAGR | C8: Karandaaz Pakistan ORIX CAPITAL | D8: 1006155292 | E8: BAFL | F8: 1182085.8 | G8: 10240.43 | H8: 10338.94 | I8: 337931.83 | J8: 382024.66 | K8: 410482.89 | R8: =SUM(F8:Q8) -> 2333104.5
A9: 7 | B9: EAGR | C9: Karandaaz Pakistan TPPL | D9: 1006155289 | E9: BAFL | F9: 102934.62 | G9: 98496.78 | H9: 99444.32 | I9: 103579.27 | J9: 853225.36 | K9: 1223477.8 | R9: =SUM(F9:Q9) -> 2481158.1
A10: 8 | B10: EAGR | C10: Karandaaz Pakistan OWN SOURCE REVENUE* | D10: 1006155288 | E10: BAFL | F10: 22522227 | G10: 32579788 | H10: 19774819 | I10: 26319781 | J10: 27920225 | K10: 24683730 | R10: =SUM(F10:Q10) -> 1.5380057e+08
A11: 9 | B11: EAGR | C11: Karandaaz Pakistan CiC | D11: 1698 | E11: BAFL | F11: 1382968.5 | G11: 2143162.6 | H11: 2346921.4 | I11: 1900670.4 | J11: 1655609 | K11: 1791145.9 | R11: =SUM(F11:Q11) -> 11220478
A12: 9 | B12: EAGR | C12: Karandaaz Pakistan Investments | D12: 2280 | E12: BAFL | I12: 2602094.9 | J12: 5711710.3 | K12: 4426338.2 | R12: =SUM(F12:Q12) -> 12740143
A13: 10 | B13: EAGR | C13: Karandaaz Pakistan Reserve* | D13: 0874-79009966-01 | E13: HBL | F13: 1968.9 | G13: 1984.79 | H13: 1936.26 | I13: 2016.42 | J13: 1967.12 | K13: 2048.56 | R13: =SUM(F13:Q13) -> 11922.05
A14: 11 | B14: EAGR | C14: Karandaaz Pakistan OWN SOURCE REVENUE* | D14: 06-02-37-20614-714-146790 | E14: HMB | F14: 503868.95 | G14: 503868.95 | H14: 503868.95 | I14: 11333.333 | J14: 11333.333 | K14: 11333.333 | R14: =SUM(F14:Q14) -> 1545606.9
A15: 12 | B15: EAGR | C15: Karandaaz Pakistan Operational | D15: 0002253139 | E15: JSBL | R15: =SUM(F15:Q15) -> 0
A16: 13 | B16: EAGR | C16: Karandaaz Pakistan OWN SOURCE REVENUE | D16: 3238390000003107 | E16: Faysal | F16: 46036892 | G16: 46551177 | H16: 54817038 | I16: 48949285 | J16: 53355378 | K16: 66883323 | R16: =SUM(F16:Q16) -> 3.1659309e+08
A17: 14 | B17: WV GCF | C17: Karandaaz Pakistan WV Greenfin | D17: 3238390000003722 | E17: Faysal | F17: 2344614 | G17: 2518745.1 | H17: 2508166.7 | I17: 2565342.9 | J17: 2251652.2 | K17: 1933481.4 | R17: =SUM(F17:Q17) -> 14122002
A18: 16 | B18: EAGR | C18: Karandaaz Pakistan Own Source Revenue | D18: 0010137809770010 | E18: ABL | R18: =SUM(F18:Q18) -> 0
A19: 17 | B19: EAGR | C19: Karandaaz Pakistan-Own Source Revenue | D19: 2001412216 | E19: SAMBA | F19: =259115.55+7670713 -> 7929828.5 | G19: =7740862.45 -> 7740862.5 | H19: 7559785.1 | I19: 7880799.8 | J19: 7696212.2 | K19: 8025306 | R19: =SUM(F19:Q19) -> 46832794 | S19: =SUM(R3:R19) -> 6.057736e+08
F20: =SUM(F3:F19) -> 90673315 | G20: =SUM(G3:G19) -> 99404954 | H20: =SUM(H3:H19) -> 94561038 | I20: =SUM(I3:I19) -> 94514267 | J20: =SUM(J3:J19) -> 1.0612461e+08 | K20: =SUM(K3:K19) -> 1.2049542e+08 | L20: =SUM(L3:L19) -> 0 | M20: =SUM(M3:M19) -> 0 | ... Q20: =SUM(Q3:Q19) -> 0 | R20: =SUM(F20:Q20) -> 6.057736e+08 | S20: Total | T20: =R20-S19 -> 0
G21: =SUM(F20:H20) -> 2.8463931e+08 | J21: =SUM(I20:K20) -> 3.2113429e+08
G22: Jul-Sept | J22: Oct-Dec
A23: BMGF | B23: SEED | C23: Account Title | D23: Bank A/c | E23: Bank Name | F23: July'25 | G23: Aug | H23: Sept | I23: October | J23: November | K23: December | L23: Jan | M23: Feb | N23: March | O23: April | P23: May | Q23: June | R23: Total
A24: 1 | B24: BMGF | C24: Karandaaz Pakistan BMGF | D24: 1006155298 | E24: BAFL | F24: 888690.75 | G24: 1185738.3 | H24: 472893.35 | I24: =432114.54+43939.69 -> 476054.23 | J24: 287403.43 | K24: 1093974.1 | R24: =SUM(F24:Q24) -> 4404754.1
A25: =A24+1 -> 2 | B25: BMGF | C25: Karandaaz Pakistan (BMGF - Ehsaas) | D25: 1009045100 | E25: BAFL | F25: 483471.76 | G25: 694131.04 | H25: 831423.35 | I25: 811374.49 | J25: 691352.67 | K25: 673279.89 | R25: =SUM(F25:Q25) -> 4185033.2
A26: =A25+1 -> 3 | B26: BMGF | C26: Karandaaz Pakistan (BMGF CT) | D26: 1009045134 | E26: BAFL | F26: 40023.53 | G26: 102031.25 | H26: 96754.54 | I26: 91072.28 | J26: 66662.41 | K26: 132754.54 | R26: =SUM(F26:Q26) -> 529298.55 | S26: =SUM(R24:R27) -> 9190627.4
A27: 4 | B27: BMGF | C27: Karandaaz Pakistan BMGF | D27: 231422152 | E27: UBL | F27: 9964.3333 | G27: 9964.3333 | H27: 9964.3333 | I27: 13848.89 | J27: 13782.99 | K27: 14016.74 | R27: =SUM(F27:Q27) -> 71541.62
F28: =SUM(F24:F27) -> 1422150.4 | G28: =SUM(G24:G27) -> 1991864.9 | H28: =SUM(H24:H27) -> 1411035.6 | I28: =SUM(I24:I27) -> 1392349.9 | J28: =SUM(J24:J27) -> 1059201.5 | K28: =SUM(K24:K26) -> 1900008.5 | L28: =SUM(L24:L26) -> 0 | M28: =SUM(M24:M26) -> 0 | N28: =SUM(N24:N26) -> 0 | O28: =SUM(O24:O26) -> 0 | P28: =SUM(P24:P26) -> 0 | Q28: =SUM(Q24:Q26) -> 0 | R28: =SUM(F28:Q28) -> 9176610.7 | S28: Total | T28: =S26-R28 -> 14016.74
G29: =SUM(F28:H28) -> 4825050.8 | J29: =SUM(I28:K28) -> 4351559.9
G30: Jul-Sept | J30: Oct-Dec
A31: FIP | B31: SEED | C31: Account Title | D31: Bank A/c | E31: Bank Name | F31: July'25 | G31: Aug | H31: Sept | I31: October | J31: November | K31: December | L31: Jan | M31: Feb | N31: March | O31: April | P31: May | Q31: June | R31: Total
A32: 1 | B32: FIP | C32: Karandaaz Pakistan FIP | D32: 1008986958 | E32: BAFL | F32: 1631218.1 | G32: 387286.15 | H32: 363066.02 | I32: 241418.67 | J32: 213903.36 | K32: 198829.8 | R32: =SUM(F32:Q32) -> 3035722.1
A33: 2 | B33: FIP | C33: Karandaaz Pakistan-FIP* | D33: 262115182 | E33: UBL | F33: 3419337.3 | G33: 3419337.3 | H33: 3419337.3 | I33: 3627097.2 | J33: 3392741.8 | K33: 3123508.9 | R33: =SUM(F33:Q33) -> 20401360
A34: 3 | B34: FIP | C34: KARANDAAZ PAKISTAN FIP | D34: 6-2-37-20614-714-153581 | E34: HMB | L34: 0 | M34: 0 | N34: 0 | O34: 0 | Q34: 0 | R34: =SUM(F34:Q34) -> 0 | S34: =SUM(R32:R34) -> 23437082
F35: =SUM(F32:F34) -> 5050555.4 | G35: =SUM(G32:G34) -> 3806623.5 | H35: =SUM(H32:H34) -> 3782403.4 | I35: =SUM(I32:I34) -> 3868515.8 | J35: =SUM(J32:J34) -> 3606645.1 | K35: =SUM(K32:K34) -> 3322338.7 | L35: =SUM(L32:L34) -> 0 | M35: =SUM(M32:M34) -> 0 | ... Q35: =SUM(Q32:Q34) -> 0 | R35: =SUM(F35:Q35) -> 23437082 | S35: Total | T35: =R35-S34 -> 0
G36: =SUM(F35:H35) -> 12639582 | J36: =SUM(I35:K35) -> 10797500
G37: Jul-Sept | J37: Oct-Dec | R37: OSR Total | S37: =S19+S44+S53 -> 6.5109774e+08
A38: RPA | B38: SEED | C38: Account Title | D38: Bank A/c | E38: Bank Name | F38: July'25 | G38: Aug | H38: Sept | I38: October | J38: November | K38: December | L38: Jan | M38: Feb | N38: March | O38: April | P38: May | Q38: June | R38: Total
A39: 1 | B39: EAGR | C39: Karandaaz Pakistan BAFL | D39: 1005639975 | E39: BAFL | F39: 2575179.5 | G39: 2798067.8 | H39: 3508992.6 | I39: =4357126.93+102577.4 -> 4459704.3 | J39: 1675173.8 | K39: 2387880.3 | R39: =SUM(F39:Q39) -> 17404998
A40: 2 | B40: EAGR | C40: Karandaaz Pakistan | D40: 9616-0001268157 | E40: JSBL | F40: -7338.28 | H40: 8045262.5 | K40: 8045262.5 | R40: =SUM(F40:Q40) -> 16083187
...

Sheet New TBILLS Mapped
A1: Bank | B1: Account Title | C1: Purchase Date | D1: Maturity Date | E1: Profit Rate (p.a) | F1: Currency | G1: Days | H1: Cheque Value | I1: Face Value | J1: Profit Pertains to this year | K1: Total Profit old tbills | L1: Accural Amount June 26
A2: UBL | B2: Karandaaz Pakistan Own Source Revenue | C2: 46086 | D2: 46268 | E2: 0.1065 | F2: PKR | G2: 182 | H2: 499950711 | I2: 526500000 | K2: =I2-H2 -> 26549289 | L2: 17213371
A3: UBL | B3: Karandaaz Pakistan Own Source Revenue | C3: 46086 | D3: 46450 | E3: 0.1092 | F3: PKR | G3: 364 | H3: 499954594 | I3: 554400000 | K3: =I3-H3 -> 54445406 | L3: 17649904
A4: UBL | B4: Karandaaz Pakistan Own Source Revenue | C4: 46147 | D4: 46226 | E4: 0.1165 | F4: PKR | G4: =D4-C4 -> 79 | H4: 975405000 | I4: 1000000000 | J4: =K4-L4 -> 6849309.9 | K4: =I4-H4 -> 24595000 | L4: 17745690
A5: UBL | B5: Karandaaz Pakistan Own Source Revenue | C5: 46156 | D5: 46240 | E5: 0.120081 | F5: PKR | G5: =D5-C5 -> 84 | H5: 486554000 | I5: 500000000 | J5: =K5-L5 -> 5762595.2 | K5: =I5-H5 -> 13446000 | L5: 7683404.8
A6: UBL | B6: Karandaaz Pakistan Own Source Revenue | C6: 46240 | D6: 46268 | E6: 0.112496 | F6: PKR | G6: =D6-C6 -> 28 | H6: 495722000 | I6: 500000000 | J6: =I6-H6 -> 4278000
A7: UBL | B7: Karandaaz Pakistan Own Source Revenue | C7: 46240 | D7: 46324 | E7: 0.114403 | F7: PKR | G7: =D7-C7 -> 84 | H7: 487173500 | I7: 500000000 | J7: =I7-H7 -> 12826500
A8: UBL | B8: Karandaaz Pakistan Own Source Revenue | C8: 46240 | D8: 46422 | E8: 0.114378 | F8: PKR | G8: =D8-C8 -> 182 | H8: 473022500 | I8: 500000000 | J8: =I8-H8 -> 26977500
J15: Total Tbills Realized | K15: =SUM(J4:J12) -> 56693905
J16: TotalBuy Sell
J17: Total Tbills + Buy Sell | K17: =SUM(K15:K16) -> 56693905
J18: Difference | K18: =K19+K17 -> 56693905
J19: BAL AS PER TB
J20: OI70108 - Profit on Tbills
E26: Monthly BreakDown
A28: Bank | B28: Account Title | C28: Purchase Date | D28: Maturity Date | E28: Profit Rate (p.a) | F28: Currency | G28: Days | H28: Cheque Value | I28: Face Value | J28: Profit Pertains to this year | K28: Total Profit old tbills | L28: Accural Amount June 26 | M28: July | N28: August | O28: Sept | P28: October | Q28: Difference Monthly total vs Actual Profit
A29: UBL | B29: Karandaaz Pakistan Own Source Revenue | C29: 46086 | D29: 46268 | E29: 0.1065 | F29: PKR | G29: 182 | H29: 499950711 | I29: 526500000 | K29: =I29-H29 -> 26549289 | L29: 17213371
A30: UBL | B30: Karandaaz Pakistan Own Source Revenue | C30: 46086 | D30: 46450 | E30: 0.1092 | F30: PKR | G30: 364 | H30: 499954594 | I30: 554400000 | K30: =I30-H30 -> 54445406 | L30: 17649904
A31: UBL | B31: Karandaaz Pakistan Own Source Revenue | C31: 46147 | D31: 46226 | E31: 0.1165 | F31: PKR | G31: =D31-C31 -> 79 | H31: 975405000 | I31: 1000000000 | J31: =K31-L31 -> 6849309.9 | K31: =I31-H31 -> 24595000 | L31: 17745690
A32: UBL | B32: Karandaaz Pakistan Own Source Revenue | C32: 46156 | D32: 46240 | E32: 0.120081 | F32: PKR | G32: =D32-C32 -> 84 | H32: 486554000 | I32: 500000000 | J32: =K32-L32 -> 5762595.2 | K32: =I32-H32 -> 13446000 | L32: 7683404.8
A34: UBL | B34: Karandaaz Pakistan Own Source Revenue | C34: 46240 | D34: 46268 | E34: 0.112496 | F34: PKR | G34: =D34-C34 -> 28 | H34: 495722000 | I34: 500000000 | J34: =I34-H34 -> 4278000 | N34: =J34*26/28 -> 3972428.6 | O34: =J34*2/28 -> 305571.43 | Q34: =SUM(M34:P34)-J34 -> 0
A35: UBL | B35: Karandaaz Pakistan Own Source Revenue | C35: 46240 | D35: 46324 | E35: 0.114403 | F35: PKR | G35: =D35-C35 -> 84 | H35: 487173500 | I35: 500000000 | J35: =I35-H35 -> 12826500 | N35: =J35*26/84 -> 3970107.1 | O35: =J35*30/84 -> 4580892.9 | P35: =J35*28/84 -> 4275500 | Q35: =SUM(M35:P35)-J35 -> 0
A36: UBL | B36: Karandaaz Pakistan Own Source Revenue | C36: 46240 | D36: 46422 | E36: 0.114378 | F36: PKR | G36: =D36-C36 -> 182 | H36: 473022500 | I36: 500000000 | J36: =I36-H36 -> 26977500 | M36: =J36*26/30 -> 23380500 | N36: =J36*31/182 -> 4595068.7 | Q36: =SUM(M36:P36)-J36 -> 998068.68
M38: =SUM(M29:M36) -> 23380500 | N38: =SUM(N29:N36) -> 12537604 | O38: =SUM(O29:O36) -> 4886464.3

Sheet Profit Rates
A1: Profit rates
A2: July | B2: August | C2: September | D2: October | E2: November | F2: December | G2: January | H2: February | I2: March | J2: April | K2: May | L2: June
A4: 1. Samba 11.30% 2. UBL 11% 3. BAFL 11% | B4: 1. Samba 11.30% 2. UBL 11% 3. BAFL/Faysal 10.75%% | C4: 1. Samba 11.30% 2. Faysal 11.25% 3. UBL 11%

Sheet Treasury Pool
A1: TREASURY POOL
C4: July | D4: August | E4: September | F4: October | G4: November | H4: December | I4: January | J4: February | K4: March | L4: April | M4: May | N4: June
B5: LR Funds | C5: 5521086012 | D5: 5521086012 | E5: 5.521086e+09
B6: OSR Funds | C6: 9310809452 | D6: 9111585024 | E6: 9.3225269e+09
B7: Investment/CDEL Funds | C7: 98909972 | D7: 434418887 | E7: 4.3678477e+08
B8: RPA A/c | C8: 250557898 | D8: 335984669 | E8: 4.7525714e+08
B9: WVGreenfin | C9: 337103978 | D9: 431711207 | E9: 4.8724681e+08
B10: Operational Funds | C10: 68242981 | D10: 55919056 | E10: 35449761
B12: Total Pool | C12: =SUM(C5:C10) -> 15586710293 | D12: =SUM(D5:D10) -> 15890704855 | E12: =SUM(E5:E10) -> 1.6278351e+10 | F12: =SUM(F5:F10) -> 0 | G12: =SUM(G5:G10) -> 0 | H12: =SUM(H5:H10) -> 0 | I12: =SUM(I5:I10) -> 0 | J12: =SUM(J5:J10) -> 0 | ... N12: =SUM(N5:N10) -> 0
D13: Average Treasury pool
D14: =AVERAGE(C12:E12) -> 1.5918589e+10

Sheet MPR
A1: MPC Meeting Date | B1: MPC Rate
A2: 46230 | B2: 0.115
A3: 46279
A4: 46321
A5: 46370
A6: 46412
A7: 46454
A8: 46503
A9: 46555

Sheet OLD T-Bills_TDR - Mapped
A1: Tbill
A2: Sr. No | B2: Bank | C2: Program | D2: Account Title | E2: Auction/Secondary | F2: T-Bill Tenure | G2: Issue Date | H2: Purchase Date | I2: Maturity Date | J2: Profit Rate (p.a) | K2: Currency | L2: No of Days | M2: Cheque Value | N2: 45869 | O2: 45900 | P2: 45930 | Q2: 45961 | R2: 45991 | S2: 46022 | T2: 46053 | U2: 46081 | V2: 46112 | W2: 46142 | X2: 46173 | Y2: 46203 | Z2: 46229 | AA2: 46260 | AB2: 46291 | AC2: 46321 | AD2: 46352 | AE2: 46382 | AF2: 46414 | AG2: 46445 | AH2: 46473 | AI2: Face Value | AJ2: Profit amount | AK2: Difference | AL2: Funds Movement date | AM2: Comments | AN2: Purchase date | AO2: Selling Date | AP2: No of Days | AQ2: Rate | AR2: Check Value | AS2: Profit | AT2: Face Value | AU2: WHT Deduction | AV2: Prin + Profit | AW2: Gain/(Loss) | AX2: Comments
A3: 1 | B3: BAFL | C3: OSR | D3: Karandaaz Pakistan Own Source Revenue | E3: Secondary | F3: 1-Month | G3: 45512 | H3: 45845 | I3: 45876 | J3: 0.109 | K3: PKR | L3: 31 | M3: 999997104 | N3: 7167102.5 | O3: 2090404.9 | P3: 0 | Q3: 0 | R3: 0 | S3: 0 | T3: 0 | U3: 0 | V3: 0 | W3: 0 | X3: 0 | Y3: 0 | AI3: 1009255000 | AJ3: 9257896 | AK3: -388.56324 | AL3: 45845 | AM3: OSR Funds
A4: 2 | B4: BAFL | C4: OSR | D4: Karandaaz Pakistan Own Source Revenue | E4: Secondary | F4: 1-Month | G4: 45848 | H4: 45849 | I4: 45876 | J4: 0.1105 | K4: PKR | L4: 27 | M4: 1983784000 | N4: 12011404 | O4: 4203991.6 | P4: 0 | Q4: 0 | R4: 0 | S4: 0 | T4: 0 | U4: 0 | V4: 0 | W4: 0 | X4: 0 | Y4: 0 | AI4: 2000000000 | AJ4: 16216000 | AK4: -603.93425 | AL4: 45849 | AM4: OSR Funds
A5: 3 | B5: HMBL | C5: OSR | D5: Karandaaz Pakistan Own Source Revenue | E5: Primary | F5: 1-Month | G5: 45848 | H5: 45848 | I5: 45876 | J5: 0.110804 | K5: PKR | L5: 28 | M5: 495786000 | N5: 3160648 | O5: 1053549.3 | P5: 0 | Q5: 0 | R5: 0 | S5: 0 | T5: 0 | U5: 0 | V5: 0 | W5: 0 | X5: 0 | Y5: 0 | AI5: 500000000 | AJ5: 4214000 | AK5: 197.29981 | AL5: 45848 | AM5: OSR Funds
A6: 4 | B6: HMBL | C6: OSR | D6: Karandaaz Pakistan Own Source Revenue | E6: Primary | F6: 3-Months | G6: 45848 | H6: 45848 | I6: 45932 | J6: 0.108626 | K6: PKR | L6: 84 | M6: 487805500 | N6: 3048645.4 | O6: 4500381.3 | P6: 4355207.7 | Q6: 290347.18 | R6: 0 | S6: 0 | T6: 0 | U6: 0 | V6: 0 | W6: 0 | X6: 0 | Y6: 0 | AI6: 500000000 | AJ6: 12194500 | AK6: 81.535375 | AL6: 45848 | AM6: OSR Funds
A7: 5 | B7: BAFL | C7: OSR | D7: Karandaaz Pakistan Own Source Revenue | E7: Primary | F7: 1-Month | G7: 45861 | H7: 45862 | I7: 45890 | J7: 0.108506 | K7: PKR | L7: 28 | M7: 123968125 | N7: 257969.86 | O7: 773909.57 | P7: 0 | Q7: 0 | R7: 0 | S7: 0 | T7: 0 | U7: 0 | V7: 0 | W7: 0 | X7: 0 | Y7: 0 | AI7: 125000000 | AJ7: 1031875 | AK7: 4.4257397 | AL7: 45862 | AM7: OSR Funds
A8: 6 | B8: BAFL | C8: OSR | D8: Karandaaz Pakistan Own Source Revenue | E8: Primary | F8: 3-Months | G8: 45861 | H8: 45862 | I8: 45946 | J8: 0.10675 | K8: PKR | L8: 84 | M8: 244005500 | N8: 499542.77 | O8: 2212260.8 | P8: 2140897.6 | Q8: 1141812 | R8: 0 | S8: 0 | T8: 0 | U8: 0 | V8: 0 | W8: 0 | X8: 0 | Y8: 0 | AI8: 250000000 | AJ8: 5994500 | AK8: 13.20137 | AL8: 45862 | AM8: OSR Funds
A9: 7 | B9: BAFL | C9: OSR | D9: Karandaaz Pakistan Own Source Revenue | E9: Primary | F9: 1-Month | G9: 45890 | H9: 45890 | I9: 45918 | J9: 0.108715 | K9: PKR | L9: 28 | M9: 123966125 | O9: 369232.25 | P9: 664618.06 | Q9: 0 | R9: 0 | S9: 0 | T9: 0 | U9: 0 | V9: 0 | W9: 0 | X9: 0 | Y9: 0 | AI9: 125000000 | AJ9: 1033875 | AK9: -24.688158 | AL9: 45890 | AM9: OSR Funds
A10: 8 | B10: BAFL | C10: OSR | D10: Karandaaz Pakistan Own Source Revenue | E10: Primary | F10: 3-Months | G10: 45890 | H10: 45890 | I10: 45974 | J10: 0.108204 | K10: PKR | L10: 84 | M10: 365888625 | O10: 1084674.3 | P10: 3254023 | Q10: 3362490.4 | R10: 1410076.6 | S10: 0 | T10: 0 | U10: 0 | V10: 0 | W10: 0 | X10: 0 | Y10: 0 | AI10: 375000000 | AJ10: 9111375 | AK10: -110.6891 | AL10: 45890 | AM10: OSR Funds
A11: 9 | B11: UBL | C11: LR | D11: Karandaaz Pakistan Own Source Revenue | E11: Primary | F11: 6-Months | G11: 45890 | H11: 45890 | I11: 46072 | J11: 0.108296 | K11: PKR | L11: 182 | M11: 237191750 | O11: 703751.17 | P11: 2111253.5 | Q11: 2181628.6 | R11: 2111253.5 | S11: 2181628.6 | T11: 2181628.6 | U11: 1337127.2 | V11: 0 | W11: 0 | X11: 0 | Y11: 0 | AI11: 250000000 | AJ11: 12808250 | AK11: 21.320427 | AL11: 45890 | AM11: Liquidity Reserve Funds
A12: 10 | B12: BAFL | C12: OSR | D12: Karandaaz Pakistan Own Source Revenue | E12: Primary | F12: 1-Month | G12: 45904 | H12: 45904 | I12: 45932 | J12: 0.107273 | K12: PKR | L12: 28 | M12: 247959500 | P12: 1894748.9 | Q12: 145749.91 | R12: 0 | S12: 0 | T12: 0 | U12: 0 | V12: 0 | W12: 0 | X12: 0 | Y12: 0 | AI12: 250000000 | AJ12: 2040500 | AK12: -1.1933753 | AL12: 45904 | AM12: OSR Funds
A13: 11 | B13: BAFL | C13: OSR | D13: Karandaaz Pakistan Own Source Revenue | E13: Primary | F13: 3-Months | G13: 45904 | H13: 45904 | I13: 45988 | J13: 0.108297 | K13: PKR | L13: 84 | M13: 487841500 | P13: 3763359 | Q13: 4487081.9 | R13: 3908103.6 | S13: 0 | T13: 0 | U13: 0 | V13: 0 | W13: 0 | X13: 0 | Y13: 0 | AI13: 500000000 | AJ13: 12158500 | AK13: 44.541759 | AL13: 45904 | AM13: OSR Funds
A14: 12 | B14: UBL | C14: OSD | D14: Karandaaz Pakistan Own Source Revenue | E14: Secondary | F14: 1-Month | G14: 45932 | H14: 45933 | I14: 45960 | J14: 0.1107 | K14: PKR | L14: 27 | M14: 2000022799 | Q14: 16377721 | R14: 0 | S14: 0 | T14: 0 | U14: 0 | V14: 0 | W14: 0 | X14: 0 | Y14: 0 | AI14: 2016400000 | AJ14: 16377201 | AK14: 519.94228 | AL14: 45933 | AM14: OSR Funds
A15: 13 | B15: UBL | C15: LR | D15: Karandaaz Pakistan Own Source Revenue | E15: Primary | F15: 1-Month | G15: 45960 | H15: 45960 | I15: 45988 | J15: 0.109858 | K15: PKR | L15: 28 | M15: 495821500 | Q15: 149232.76 | R15: 4029284.6 | S15: 0 | T15: 0 | U15: 0 | V15: 0 | W15: 0 | X15: 0 | Y15: 0 | AI15: 500000000 | AJ15: 4178500 | AK15: 17.352647 | AL15: 45960 | AM15: Liquidity Reserve Funds
A16: 14 | B16: UBL | C16: LR | D16: Karandaaz Pakistan Own Source Revenue | E16: Primary | F16: 3-Months | G16: 45960 | H16: 45960 | I16: 46044 | J16: 0.110155 | K16: PKR | L16: 84 | M16: 487638000 | Q16: 147166.48 | R16: 4414994.3 | S16: 4562160.8 | T16: 3237662.5 | U16: 0 | V16: 0 | W16: 0 | X16: 0 | Y16: 0 | AI16: 500000000 | AJ16: 12362000 | AK16: -15.981479 | AL16: 45960 | AM16: Liquidity Reserve Funds
A17: 15 | B17: UBL | C17: LR | D17: Karandaaz Pakistan Own Source Revenue | E17: Secondary | F17: 6-Months | G17: 46086 | H17: 46086 | I17: 46268 | J17: 0.1065 | K17: PKR | L17: 182 | M17: 499950711 | V17: 3938652.8 | W17: 4376280.9 | X17: 4522156.9 | Y17: 4376280.9 | Z17: 4522156.9 | AA17: 4522156.9 | AB17: 291752.06 | AI17: 526500000 | AJ17: =AI17-M17 -> 26549289 | AK17: =AJ17-SUM(V17:AB17) -> -148.34606 | AM17: 0 | AN17: 0 | AO17: 0 | AP17: 0 | AQ17: 0 | AR17: 0 | AS17: 0 | AT17: 0 | AU17: 526500000 | AV17: 26549289 | AW17: 148.34606 | AX17: 46086 | AY17: Liquidity Reserve Funds
A18: 16 | B18: UBL | C18: LR | D18: Karandaaz Pakistan Own Source Revenue | E18: Secondary | F18: 12-Months | G18: 46086 | H18: 46086 | I18: 46450 | J18: 0.1092 | K18: PKR | L18: 364 | M18: 499954594 | V18: 4038537.3 | W18: 4487263.7 | X18: 4636839.2 | Y18: 4487263.7 | Z18: 4636839.2 | AA18: 4636839.2 | AB18: 4487263.7 | AC18: 4636839.2 | AD18: 4487263.7 | AE18: 4636839.2 | AF18: 4636839.2 | AG18: 4188112.8 | AH18: 447420.15 | AI18: 554400000 | AJ18: =AI18-M18 -> 54445406 | AK18: =SUM(V18:AH18)-AJ18 -> -1246.0117 | AM18: 4487263.7 | AN18: 4636839.2 | AO18: 4636839.2 | AP18: 4188112.8 | AQ18: 598301.83 | AR18: 0 | AS18: 0 | AT18: 0 | AU18: 554400000 | AV18: 54445406 | AW18: 60.208184 | AX18: 46086 | AY18: Liquidity Reserve Funds
A19: 17 | B19: UBL | C19: LR | D19: Karandaaz Pakistan Own Source Revenue | E19: Secondary | F19: 3-Months | G19: 46147 | H19: 46147 | I19: 46226 | J19: 0.1165 | K19: PKR | L19: =I19-H19 -> 79 | M19: 975405000 | X19: 8405853.2 | Y19: 9339836.9 | Z19: 6849213.7 | AI19: 1000000000 | AJ19: =AI19-M19 -> 24595000 | AK19: =AJ19-SUM(W19:Z19) -> 96.116438
A20: 18 | B20: UBL | C20: LR | D20: Karandaaz Pakistan Own Source Revenue | F20: 1-Month | G20: 46156 | H20: 46156 | I20: 46184 | J20: 0.113239 | K20: PKR | L20: =I20-H20 -> 28 | M20: 495694000 | X20: 2768148.1 | Y20: 1537860.1 | AI20: 500000000 | AJ20: =AI20-M20 -> 4306000 | AK20: =AJ20-SUM(W20:Z20) -> -8.2198575
A21: 19 | B21: UBL | C21: LR | D21: Karandaaz Pakistan Own Source Revenue | G21: 46156 | H21: 46156 | I21: 46240 | J21: 0.120081 | K21: PKR | L21: =I21-H21 -> 84 | M21: 486554000 | X21: 2881276.8 | Y21: 4802128 | Z21: 4802128 | AA21: 960425.6 | AI21: 500000000 | AJ21: =AI21-M21 -> 13446000 | AK21: =AJ21-SUM(W21:AA21) -> 41.552285
A22: 20 | B22: UBL | C22: LR | D22: Karandaaz Pakistan Own Source Revenue | G22: 46164 | H22: 46164 | I22: 46197 | J22: 0.119 | K22: PKR | L22: =I22-H22 -> 33 | M22: 494678000 | X22: 1612785.8 | Y22: 3709407.4 | AI22: 500000000 | AJ22: =AI22-M22 -> 5322000 | AK22: =AJ22-SUM(W22:AA22) -> -193.16712
N26: =SUM(N3:N18) -> 26145313 | O26: =SUM(O3:O18) -> 16992155 | P26: =SUM(P3:P18) -> 18184108 | Q26: =SUM(Q3:Q18) -> 28283230 | R26: =SUM(R3:R18) -> 15873713 | S26: =SUM(S3:S18) -> 6743789.4 | T26: =SUM(T3:T18) -> 5419291.1 | U26: =SUM(U3:U18) -> 1337127.2 | V26: =SUM(V3:V18) -> 7977190.1 | W26: =SUM(W3:W21) -> 8863544.6 | X26: =SUM(X3:X22) -> 24827060 | Y26: =SUM(Y3:Y22) -> 28252777 | Z26: =SUM(N26:Y26) -> 1.888993e+08
N27: =SUM(N26:P26) -> 61321576 | Q27: =SUM(Q26:S26) -> 50900732 | T27: =SUM(T26:V26) -> 14733608 | W27: =SUM(W26:Y26) -> 61943382
O28: Jul-Sept | R28: Oct-Dec | U28: Jan-Mar | X28: APR-JUNE
Y29: Tbills Total | Z29: =SUM(N3:U17)+SUM(X20:Y20,X22:Y22) -> 1.2860693e+08
U30: Total Tbill+BuySell | V30: =Z29+'New Buy Sell Mapped'!J10 -> 1.4820559e+08
T31: June 30th TB | U31: Profit on T-Bills | V31: -1.7707407e+08
U32: OI70108 | V32: =V31+V30 -> -28868489
U35: total BUYSELL | V35: ='New Buy Sell Mapped'!J10 -> 19598658
U59: 50900732

Sheet Sheet1
M6: =M7-L7+1 -> 27
K7: 46086 | L7: 46086 | M7: 46112 | T7: 46268 | U7: 0.1065 | V7: PKR | W7: 182 | X7: 499950711
K12: 46086 | L12: 46086 | T12: 46450 | U12: 0.1092 | V12: PKR | W12: 364 | X12: 499954594

Sheet T-Bill Data
A1: Bank | B1: Program | C1: Account Title | D1: Purchase Date | E1: Maturity Date | F1: Profit Rate (p.a) | G1: Currency | H1: No of Days | I1: Cheque Value | J1: Face Value | K1: Profit amount | M1: Profit on T-bill BAL AS OF October | N1: ='[57]TB AS OF 31ST OCT'!N542 -> -68360347
A2: BAFL | B2: OSR | C2: Karandaaz Pakistan Own Source Revenue | D2: 45845 | E2: 45876 | F2: 0.109 | G2: PKR | H2: =E2-D2 -> 31 | I2: 999997104 | J2: 1009255000 | K2: =J2-I2 -> 9257896 | M2: Our working | N2: =SUM(K2:K10) -> 68360347
A3: BAFL | B3: OSR | C3: Karandaaz Pakistan Own Source Revenue | D3: 45849 | E3: 45876 | F3: 0.1105 | G3: PKR | H3: =E3-D3 -> 27 | I3: 1983784000 | J3: 2000000000 | K3: =J3-I3 -> 16216000 | N3: =N2+N1 -> 0.2
A4: HMBL | B4: OSR | C4: Karandaaz Pakistan Own Source Revenue | D4: 45848 | E4: 45876 | F4: 0.110804 | G4: PKR | H4: =E4-D4 -> 28 | I4: 495786000 | J4: 500000000 | K4: =J4-I4 -> 4214000
A5: HMBL | B5: OSR | C5: Karandaaz Pakistan Own Source Revenue | D5: 45848 | E5: 45932 | F5: 0.108626 | G5: PKR | H5: =E5-D5 -> 84 | I5: 487805500 | J5: 500000000 | K5: =J5-I5 -> 12194500
A6: BAFL | B6: OSR | C6: Karandaaz Pakistan Own Source Revenue | D6: 45862 | E6: 45890 | F6: 0.108506 | G6: PKR | H6: =E6-D6 -> 28 | I6: 123968125 | J6: 125000000 | K6: =J6-I6 -> 1031875
A7: BAFL | B7: OSR | C7: Karandaaz Pakistan Own Source Revenue | D7: 45862 | E7: 45946 | F7: 0.10675 | G7: PKR | H7: =E7-D7 -> 84 | I7: 244005500 | J7: 250000000 | K7: =J7-I7 -> 5994500
A8: BAFL | B8: OSR | C8: Karandaaz Pakistan Own Source Revenue | D8: 45890 | E8: 45918 | F8: 0.108715 | G8: PKR | H8: =E8-D8 -> 28 | I8: 123966125 | J8: 125000000 | K8: =J8-I8 -> 1033875
A9: UBL | B9: LR | C9: Karandaaz Pakistan Own Source Revenue | D9: 45933 | E9: 45960 | F9: 0.1107 | G9: PKR | H9: =E9-D9 -> 27 | I9: 2000022799 | J9: 2016400000 | K9: =J9-I9 -> 16377201
A10: BAFL | B10: OSR | C10: Karandaaz Pakistan Own Source Revenue | D10: 45904 | E10: 45932 | F10: 0.107273 | G10: PKR | H10: =E10-D10 -> 28 | I10: 247959500 | J10: 250000000 | K10: =J10-I10 -> 2040500
K11: =SUM(K2:K10) -> 68360347
B15: Unrealized T BILL
A16: Sr. No | B16: Bank | C16: Program | D16: Account Title | E16: Auction/Secondary | F16: T-Bill Tenure | G16: Issue Date | H16: Purchase Date | I16: Maturity Date | J16: Profit Rate (p.a) | K16: Currency | L16: No of Days | M16: Cheque Value | N16: 45869 | O16: 45900 | P16: 45930 | Q16: 45961 | R16: 45991 | S16: 46022 | T16: 46053 | U16: 46081 | V16: 46112 | W16: 46142 | X16: 46173 | Y16: 46203 | Z16: Face Value | AA16: Profit amount | AB16: Difference | AC16: Funds Movement date | AD16: Comments
A17: 22 | B17: UBL | C17: LR | D17: Karandaaz Pakistan Own Source Revenue | E17: Primary | F17: 6-Months | G17: 45890 | H17: 45890 | I17: 46072 | J17: 0.108296 | K17: PKR | L17: =I17-H17 -> 182 | M17: 237191750 | O17: 774125 | P17: 2111250 | Q17: 2181625 | R17: 2111250 | S17: 2181625 | T17: 2181625 | U17: 1266750 | Z17: 250000000 | AA17: =Z17-M17 -> 12808250 | AB17: =SUM(N17:Y17)-AA17 -> 0 | AC17: 45890 | AD17: Liquidity Reserve Funds
A18: 24 | B18: BAFL | C18: OSR | D18: Karandaaz Pakistan Own Source Revenue | E18: Primary | F18: 3-Months | G18: 45904 | H18: 45904 | I18: 45988 | J18: 0.108297 | K18: PKR | L18: =I18-H18 -> 84 | M18: 487841500 | P18: 3908089.3 | Q18: 4487065.5 | R18: 3763345.2 | Z18: 500000000 | AA18: =Z18-M18 -> 12158500 | AB18: =SUM(N18:Y18)-AA18 -> 0 | AC18: 45904 | AD18: OSR Funds
A19: 25 | B19: UBL | C19: LR | D19: Karandaaz Pakistan Own Source Revenue | E19: Primary | F19: 1-Month | G19: 45960 | H19: 45960 | I19: 45988 | J19: 0.109858 | K19: PKR | L19: =I19-H19 -> 28 | M19: 495821500 | Q19: 298464.29 | R19: 3880035.7 | Z19: 500000000 | AA19: =Z19-M19 -> 4178500 | AB19: =SUM(N19:Y19)-AA19 -> 0 | AC19: 45960 | AD19: Liquidity Reserve Funds
A20: 26 | B20: UBL | C20: LR | D20: Karandaaz Pakistan Own Source Revenue | E20: Primary | F20: 3-Months | G20: 45960 | H20: 45960 | I20: 46044 | J20: 0.110155 | K20: PKR | L20: =I20-H20 -> 84 | M20: 487638000 | Q20: 294333.33 | R20: 4415000 | S20: 4562166.7 | T20: 3090500 | Z20: 500000000 | AA20: =Z20-M20 -> 12362000 | AB20: =SUM(N20:Y20)-AA20 -> 0 | AC20: 45960 | AD20: Liquidity Reserve Funds
